Workbook
Name Stocks__Total_40: 'Investment Portfolio'!$B$6:$B$7
Name UPDATE: 'Data Sheet'!$E$1

Sheet Profit & Loss
A1: ='Data Sheet'!B1 -> TATA CONSULTANCY SERVICES LTD | H1: =UPDATE | M1: SCREENER.IN
A3: Narration | B3: ='Data Sheet'!B16 -> 42825 | C3: ='Data Sheet'!C16 -> 43190 | D3: ='Data Sheet'!D16 -> 43555 | E3: ='Data Sheet'!E16 -> 43921 | F3: ='Data Sheet'!F16 -> 44286 | G3: ='Data Sheet'!G16 -> 44651 | H3: ='Data Sheet'!H16 -> 45016 | I3: ='Data Sheet'!I16 -> 45382 | ... K3: ='Data Sheet'!K16 -> 46112 | L3: Trailing | M3: Best Case | N3: Worst Case
A4: Sales | B4: ='Data Sheet'!B17 -> 117966 | C4: ='Data Sheet'!C17 -> 123104 | D4: ='Data Sheet'!D17 -> 146463 | E4: ='Data Sheet'!E17 -> 156949 | F4: ='Data Sheet'!F17 -> 164177 | G4: ='Data Sheet'!G17 -> 191754 | H4: ='Data Sheet'!H17 -> 225458 | I4: ='Data Sheet'!I17 -> 240893 | ... K4: ='Data Sheet'!K17 -> 267021 | L4: =SUM(Quarters!H4:K4) -> 267021 | M4: =$K4+M23*K4 -> 282513.15 | N4: =$K4+N23*L4 -> 279253.87
A5: Expenses | B5: =SUM('Data Sheet'!B18,'Data Sheet'!B20:B24, -1*'Data Sheet'!B19) -> 85655 | C5: =SUM('Data Sheet'!C18,'Data Sheet'!C20:C24, -1*'Data Sheet'!C19) -> 90588 | D5: =SUM('Data Sheet'!D18,'Data Sheet'!D20:D24, -1*'Data Sheet'!D19) -> 106957 | E5: =SUM('Data Sheet'!E18,'Data Sheet'!E20:E24, -1*'Data Sheet'!E19) -> 114840 | F5: =SUM('Data Sheet'!F18,'Data Sheet'!F20:F24, -1*'Data Sheet'!F19) -> 117631 | G5: =SUM('Data Sheet'!G18,'Data Sheet'!G20:G24, -1*'Data Sheet'!G19) -> 138697 | H5: =SUM('Data Sheet'!H18,'Data Sheet'!H20:H24, -1*'Data Sheet'!H19) -> 166199 | I5: =SUM('Data Sheet'!I18,'Data Sheet'!I20:I24, -1*'Data Sheet'!I19) -> 176597 | ... K5: =SUM('Data Sheet'!K18,'Data Sheet'!K20:K24, -1*'Data Sheet'!K19) -> 194623 | L5: =SUM(Quarters!H5:K5) -> 194623 | M5: =M4-M6 -> 205914.73 | N5: =N4-N6 -> 204577.3
A6: Operating Profit | B6: =B4-B5 -> 32311 | C6: =C4-C5 -> 32516 | D6: =D4-D5 -> 39506 | E6: =E4-E5 -> 42109 | F6: =F4-F5 -> 46546 | G6: =G4-G5 -> 53057 | H6: =H4-H5 -> 59259 | I6: =I4-I5 -> 64296 | ... K6: =K4-K5 -> 72398 | L6: =SUM(Quarters!H6:K6) -> 72398 | M6: =M4*M24 -> 76598.422 | N6: =N4*N24 -> 74676.567
A7: Other Income | B7: ='Data Sheet'!B25 -> 4221 | C7: ='Data Sheet'!C25 -> 3642 | D7: ='Data Sheet'!D25 -> 4311 | E7: ='Data Sheet'!E25 -> 4592 | F7: ='Data Sheet'!F25 -> 1916 | G7: ='Data Sheet'!G25 -> 4018 | H7: ='Data Sheet'!H25 -> 3449 | I7: ='Data Sheet'!I25 -> 3464 | ... K7: ='Data Sheet'!K25 -> -124 | L7: =SUM(Quarters!H7:K7) -> -124 | M7: 0 | N7: 0
A8: Depreciation | B8: ='Data Sheet'!B26 -> 1987 | C8: ='Data Sheet'!C26 -> 2014 | D8: ='Data Sheet'!D26 -> 2056 | E8: ='Data Sheet'!E26 -> 3529 | F8: ='Data Sheet'!F26 -> 4065 | G8: ='Data Sheet'!G26 -> 4604 | H8: ='Data Sheet'!H26 -> 5022 | I8: ='Data Sheet'!I26 -> 4985 | ... K8: ='Data Sheet'!K26 -> 5560 | L8: =SUM(Quarters!H8:K8) -> 5560 | M8: =+$L8 -> 5560 | N8: =+$L8 -> 5560
A9: Interest | B9: ='Data Sheet'!B27 -> 32 | C9: ='Data Sheet'!C27 -> 52 | D9: ='Data Sheet'!D27 -> 198 | E9: ='Data Sheet'!E27 -> 924 | F9: ='Data Sheet'!F27 -> 637 | G9: ='Data Sheet'!G27 -> 784 | H9: ='Data Sheet'!H27 -> 779 | I9: ='Data Sheet'!I27 -> 778 | ... K9: ='Data Sheet'!K27 -> 1227 | L9: =SUM(Quarters!H9:K9) -> 1227 | M9: =+$L9 -> 1227 | N9: =+$L9 -> 1227
A10: Profit before tax | B10: ='Data Sheet'!B28 -> 34513 | C10: ='Data Sheet'!C28 -> 34092 | D10: ='Data Sheet'!D28 -> 41563 | E10: ='Data Sheet'!E28 -> 42248 | F10: ='Data Sheet'!F28 -> 43760 | G10: ='Data Sheet'!G28 -> 51687 | H10: ='Data Sheet'!H28 -> 56907 | I10: ='Data Sheet'!I28 -> 61997 | ... K10: ='Data Sheet'!K28 -> 65487 | L10: =SUM(Quarters!H10:K10) -> 65487 | M10: =M6+M7-SUM(M8:M9) -> 69811.422 | N10: =N6+N7-SUM(N8:N9) -> 67889.567
A11: Tax | B11: ='Data Sheet'!B29 -> 8156 | C11: ='Data Sheet'!C29 -> 8212 | D11: ='Data Sheet'!D29 -> 10001 | E11: ='Data Sheet'!E29 -> 9801 | F11: ='Data Sheet'!F29 -> 11198 | G11: ='Data Sheet'!G29 -> 13238 | H11: ='Data Sheet'!H29 -> 14604 | I11: ='Data Sheet'!I29 -> 15898 | ... K11: ='Data Sheet'!K29 -> 16033 | L11: =SUM(Quarters!H11:K11) -> 16033 | M11: =IF($L10>0,$L11/$L10,0) -> 0.24482722 | N11: =IF($L10>0,$L11/$L10,0) -> 0.24482722
A12: Net profit | B12: ='Data Sheet'!B30 -> 26289 | C12: ='Data Sheet'!C30 -> 25826 | D12: ='Data Sheet'!D30 -> 31472 | E12: ='Data Sheet'!E30 -> 32340 | F12: ='Data Sheet'!F30 -> 32430 | G12: ='Data Sheet'!G30 -> 38327 | H12: ='Data Sheet'!H30 -> 42147 | I12: ='Data Sheet'!I30 -> 45908 | ... K12: ='Data Sheet'!K30 -> 49210 | L12: =SUM(Quarters!H12:K12) -> 49210 | M12: =M10-M11*M10 -> 52719.686 | N12: =N10-N11*N10 -> 51268.353
A13: EPS | B13: =IF('Data Sheet'!B93>0,B12/'Data Sheet'!B93,0) -> 66.708112 | C13: =IF('Data Sheet'!C93>0,C12/'Data Sheet'!C93,0) -> 67.455467 | D13: =IF('Data Sheet'!D93>0,D12/'Data Sheet'!D93,0) -> 83.871655 | E13: =IF('Data Sheet'!E93>0,E12/'Data Sheet'!E93,0) -> 86.184842 | F13: =IF('Data Sheet'!F93>0,F12/'Data Sheet'!F93,0) -> 87.669974 | G13: =IF('Data Sheet'!G93>0,G12/'Data Sheet'!G93,0) -> 104.74434 | H13: =IF('Data Sheet'!H93>0,H12/'Data Sheet'!H93,0) -> 115.18406 | I13: =IF('Data Sheet'!I93>0,I12/'Data Sheet'!I93,0) -> 126.88428 | ... K13: =IF('Data Sheet'!K93>0,K12/'Data Sheet'!K93,0) -> 136.01061 | L13: =IF('Data Sheet'!$B6>0,'Profit & Loss'!L12/'Data Sheet'!$B6,0) -> 136.01383 | M13: =IF('Data Sheet'!$B6>0,'Profit & Loss'!M12/'Data Sheet'!$B6,0) -> 145.71442 | N13: =IF('Data Sheet'!$B6>0,'Profit & Loss'!N12/'Data Sheet'!$B6,0) -> 141.70301
A14: Price to earning | B14: =IF(B15>0,B15/B13,"") -> 18.227168 | C14: =IF(C15>0,C15/C13,"") -> 21.118822 | D14: =IF(D15>0,D15/D13,"") -> 23.865631 | E14: =IF(E15>0,E15/E13,"") -> 21.188181 | F14: =IF(F15>0,F15/F13,"") -> 36.247872 | G14: =IF(G15>0,G15/G13,"") -> 35.705511 | H14: =IF(H15>0,H15/H13,"") -> 27.832844 | I14: =IF(I15>0,I15/I13,"") -> 30.549885 | ... K14: =IF(K15>0,K15/K13,"") -> 17.343499 | L14: =IF(L13>0,L15/L13,0) -> 18.784119 | M14: =M25 -> 23.387504 | N14: =N25 -> 18.784119
A15: Price | B15: ='Data Sheet'!B90 -> 1215.9 | C15: ='Data Sheet'!C90 -> 1424.58 | D15: ='Data Sheet'!D90 -> 2001.65 | E15: ='Data Sheet'!E90 -> 1826.1 | F15: ='Data Sheet'!F90 -> 3177.85 | G15: ='Data Sheet'!G90 -> 3739.95 | H15: ='Data Sheet'!H90 -> 3205.9 | I15: ='Data Sheet'!I90 -> 3876.3 | ... K15: ='Data Sheet'!K90 -> 2358.9 | L15: ='Data Sheet'!B8 -> 2554.9 | M15: =M13*M14 -> 3407.8966 | N15: =N13*N14 -> 2661.7662
A17: RATIOS:
A18: Dividend Payout | B18: =IF('Data Sheet'!B30>0, 'Data Sheet'!B31/'Data Sheet'!B30, 0) -> 0.35220054 | C18: =IF('Data Sheet'!C30>0, 'Data Sheet'!C31/'Data Sheet'!C30, 0) -> 0.36978239 | D18: =IF('Data Sheet'!D30>0, 'Data Sheet'!D31/'Data Sheet'!D30, 0) -> 0.3574606 | E18: =IF('Data Sheet'!E30>0, 'Data Sheet'!E31/'Data Sheet'!E30, 0) -> 0.84647495 | F18: =IF('Data Sheet'!F30>0, 'Data Sheet'!F31/'Data Sheet'!F30, 0) -> 0.43354918 | G18: =IF('Data Sheet'!G30>0, 'Data Sheet'!G31/'Data Sheet'!G30, 0) -> 0.41062436 | H18: =IF('Data Sheet'!H30>0, 'Data Sheet'!H31/'Data Sheet'!H30, 0) -> 0.99864759 | I18: =IF('Data Sheet'!I30>0, 'Data Sheet'!I31/'Data Sheet'!I30, 0) -> 0.57562952 | ... K18: =IF('Data Sheet'!K30>0, 'Data Sheet'!K31/'Data Sheet'!K30, 0) -> 0.80918512
A19: OPM | B19: =IF(B6>0,B6/B4,0) -> 0.27390095 | C19: =IF(C6>0,C6/C4,0) -> 0.26413439 | D19: =IF(D6>0,D6/D4,0) -> 0.26973365 | E19: =IF(E6>0,E6/E4,0) -> 0.26829734 | F19: =IF(F6>0,F6/F4,0) -> 0.28351109 | G19: =IF(G6>0,G6/G4,0) -> 0.27669305 | H19: =IF(H6>0,H6/H4,0) -> 0.26283831 | I19: =IF(I6>0,I6/I4,0) -> 0.26690688 | ... L19: =IF(L6>0,L6/L4,0) -> 0.27113223
G22: TRENDS: | H22: 10 YEARS | I22: 7 YEARS | J22: 5 YEARS | K22: 3 YEARS | L22: RECENT | M22: BEST | N22: WORST
G23: Sales Growth | H23: =IF(B4=0,"",POWER($K4/B4,1/9)-1) -> 0.095017227 | I23: =IF(D4=0,"",POWER($K4/D4,1/7)-1) -> 0.089581302 | J23: =IF(F4=0,"",POWER($K4/F4,1/5)-1) -> 0.10216501 | K23: =IF(H4=0,"",POWER($K4/H4, 1/3)-1) -> 0.058018486 | L23: =IF(ISERROR(MAX(IF(J4=0,"",(K4-J4)/J4),IF(K4=0,"",(L4-K4)/K4))),"",MAX(IF(J4=0,"",(K4-J4)/J4),IF(K4=0,"",(L4-K4)/K4))) -> 0.04581238 | M23: =MAX(K23:L23) -> 0.058018486 | N23: =MIN(H23:L23) -> 0.04581238
G24: OPM | H24: =IF(SUM(B4:$K$4)=0,"",SUMPRODUCT(B19:$K$19,B4:$K$4)/SUM(B4:$K$4)) -> 0.26965358 | I24: =IF(SUM(E4:$K$4)=0,"",SUMPRODUCT(E19:$K$19,E4:$K$4)/SUM(E4:$K$4)) -> 0.26976457 | J24: =IF(SUM(G4:$K$4)=0,"",SUMPRODUCT(G19:$K$19,G4:$K$4)/SUM(G4:$K$4)) -> 0.26804778 | K24: =IF(SUM(I4:$K$4)=0, "", SUMPRODUCT(I19:$K$19,I4:$K$4)/SUM(I4:$K$4)) -> 0.26741462 | L24: =L19 -> 0.27113223 | M24: =MAX(K24:L24) -> 0.27113223 | N24: =MIN(H24:L24) -> 0.26741462
G25: Price to Earning | H25: =IF(ISERROR(AVERAGEIF(B14:$L14,">0")),"",AVERAGEIF(B14:$L14,">0")) -> 25.248731 | I25: =IF(ISERROR(AVERAGEIF(E14:$L14,">0")),"",AVERAGEIF(E14:$L14,">0")) -> 26.815553 | J25: =IF(ISERROR(AVERAGEIF(G14:$L14,">0")),"",AVERAGEIF(G14:$L14,">0")) -> 26.181395 | K25: =IF(ISERROR(AVERAGEIF(I14:$L14,">0")),"",AVERAGEIF(I14:$L14,">0")) -> 23.387504 | L25: =L14 -> 18.784119 | M25: =MAX(K25:L25) -> 23.387504 | N25: =MIN(H25:L25) -> 18.784119

Sheet Quarters
A1: ='Profit & Loss'!A1 -> TATA CONSULTANCY SERVICES LTD | E1: =UPDATE | J1: SCREENER.IN
A3: Narration | B3: ='Data Sheet'!B41 -> 45291 | C3: ='Data Sheet'!C41 -> 45382 | D3: ='Data Sheet'!D41 -> 45473 | E3: ='Data Sheet'!E41 -> 45565 | F3: ='Data Sheet'!F41 -> 45657 | G3: ='Data Sheet'!G41 -> 45747 | H3: ='Data Sheet'!H41 -> 45838 | I3: ='Data Sheet'!I41 -> 45930 | ... K3: ='Data Sheet'!K41 -> 46112
A4: Sales | B4: ='Data Sheet'!B42 -> 60583 | C4: ='Data Sheet'!C42 -> 61237 | D4: ='Data Sheet'!D42 -> 62613 | E4: ='Data Sheet'!E42 -> 64259 | F4: ='Data Sheet'!F42 -> 63973 | G4: ='Data Sheet'!G42 -> 64479 | H4: ='Data Sheet'!H42 -> 63437 | I4: ='Data Sheet'!I42 -> 65799 | ... K4: ='Data Sheet'!K42 -> 70698
A5: Expenses | B5: ='Data Sheet'!B43 -> 44195 | C5: ='Data Sheet'!C43 -> 44073 | D5: ='Data Sheet'!D43 -> 45951 | E5: ='Data Sheet'!E43 -> 47528 | F5: ='Data Sheet'!F43 -> 46939 | G5: ='Data Sheet'!G43 -> 47499 | H5: ='Data Sheet'!H43 -> 46562 | I5: ='Data Sheet'!I43 -> 47821 | ... K5: ='Data Sheet'!K43 -> 51422
A6: Operating Profit | B6: ='Data Sheet'!B50 -> 16388 | C6: ='Data Sheet'!C50 -> 17164 | D6: ='Data Sheet'!D50 -> 16662 | E6: ='Data Sheet'!E50 -> 16731 | F6: ='Data Sheet'!F50 -> 17034 | G6: ='Data Sheet'!G50 -> 16980 | H6: ='Data Sheet'!H50 -> 16875 | I6: ='Data Sheet'!I50 -> 17978 | ... K6: ='Data Sheet'!K50 -> 19276
A7: Other Income | B7: ='Data Sheet'!B44 -> -96 | C7: ='Data Sheet'!C44 -> 1157 | D7: ='Data Sheet'!D44 -> 962 | E7: ='Data Sheet'!E44 -> 729 | F7: ='Data Sheet'!F44 -> 1243 | G7: ='Data Sheet'!G44 -> 1028 | H7: ='Data Sheet'!H44 -> 1660 | I7: ='Data Sheet'!I44 -> -268 | ... K7: ='Data Sheet'!K44 -> 757
A8: Depreciation | B8: ='Data Sheet'!B45 -> 1233 | C8: ='Data Sheet'!C45 -> 1246 | D8: ='Data Sheet'!D45 -> 1220 | E8: ='Data Sheet'!E45 -> 1266 | F8: ='Data Sheet'!F45 -> 1377 | G8: ='Data Sheet'!G45 -> 1379 | H8: ='Data Sheet'!H45 -> 1361 | I8: ='Data Sheet'!I45 -> 1413 | ... K8: ='Data Sheet'!K45 -> 1406
A9: Interest | B9: ='Data Sheet'!B46 -> 230 | C9: ='Data Sheet'!C46 -> 226 | D9: ='Data Sheet'!D46 -> 173 | E9: ='Data Sheet'!E46 -> 162 | F9: ='Data Sheet'!F46 -> 234 | G9: ='Data Sheet'!G46 -> 227 | H9: ='Data Sheet'!H46 -> 195 | I9: ='Data Sheet'!I46 -> 229 | ... K9: ='Data Sheet'!K46 -> 265
A10: Profit before tax | B10: ='Data Sheet'!B47 -> 14829 | C10: ='Data Sheet'!C47 -> 16849 | D10: ='Data Sheet'!D47 -> 16231 | E10: ='Data Sheet'!E47 -> 16032 | F10: ='Data Sheet'!F47 -> 16666 | G10: ='Data Sheet'!G47 -> 16402 | H10: ='Data Sheet'!H47 -> 16979 | I10: ='Data Sheet'!I47 -> 16068 | ... K10: ='Data Sheet'!K47 -> 18362
A11: Tax | B11: ='Data Sheet'!B48 -> 3732 | C11: ='Data Sheet'!C48 -> 4347 | D11: ='Data Sheet'!D48 -> 4126 | E11: ='Data Sheet'!E48 -> 4077 | F11: ='Data Sheet'!F48 -> 4222 | G11: ='Data Sheet'!G48 -> 4109 | H11: ='Data Sheet'!H48 -> 4160 | I11: ='Data Sheet'!I48 -> 3937 | ... K11: ='Data Sheet'!K48 -> 4578
A12: Net profit | B12: ='Data Sheet'!B49 -> 11058 | C12: ='Data Sheet'!C49 -> 12434 | D12: ='Data Sheet'!D49 -> 12040 | E12: ='Data Sheet'!E49 -> 11909 | F12: ='Data Sheet'!F49 -> 12380 | G12: ='Data Sheet'!G49 -> 12224 | H12: ='Data Sheet'!H49 -> 12760 | I12: ='Data Sheet'!I49 -> 12075 | ... K12: ='Data Sheet'!K49 -> 13718
A14: OPM | B14: =IF(B4>0,B6/B4,"") -> 0.27050493 | C14: =IF(C4>0,C6/C4,"") -> 0.28028806 | D14: =IF(D4>0,D6/D4,"") -> 0.26611087 | E14: =IF(E4>0,E6/E4,"") -> 0.2603682 | F14: =IF(F4>0,F6/F4,"") -> 0.26626858 | G14: =IF(G4>0,G6/G4,"") -> 0.26334155 | H14: =IF(H4>0,H6/H4,"") -> 0.26601195 | I14: =IF(I4>0,I6/I4,"") -> 0.27322604 | ... K14: =IF(K4>0,K6/K4,"") -> 0.27265269

Sheet Balance Sheet
A1: ='Profit & Loss'!A1 -> TATA CONSULTANCY SERVICES LTD | E1: =UPDATE | J1: SCREENER.IN
A3: Narration | B3: ='Data Sheet'!B56 -> 42825 | C3: ='Data Sheet'!C56 -> 43190 | D3: ='Data Sheet'!D56 -> 43555 | E3: ='Data Sheet'!E56 -> 43921 | F3: ='Data Sheet'!F56 -> 44286 | G3: ='Data Sheet'!G56 -> 44651 | H3: ='Data Sheet'!H56 -> 45016 | I3: ='Data Sheet'!I56 -> 45382 | ... K3: ='Data Sheet'!K56 -> 46112
A4: Equity Share Capital | B4: ='Data Sheet'!B57 -> 197 | C4: ='Data Sheet'!C57 -> 191 | D4: ='Data Sheet'!D57 -> 375 | E4: ='Data Sheet'!E57 -> 375 | F4: ='Data Sheet'!F57 -> 370 | G4: ='Data Sheet'!G57 -> 366 | H4: ='Data Sheet'!H57 -> 366 | I4: ='Data Sheet'!I57 -> 362 | ... K4: ='Data Sheet'!K57 -> 362
A5: Reserves | B5: ='Data Sheet'!B58 -> 86017 | C5: ='Data Sheet'!C58 -> 84937 | D5: ='Data Sheet'!D58 -> 89071 | E5: ='Data Sheet'!E58 -> 83751 | F5: ='Data Sheet'!F58 -> 86063 | G5: ='Data Sheet'!G58 -> 88773 | H5: ='Data Sheet'!H58 -> 90058 | I5: ='Data Sheet'!I58 -> 90127 | ... K5: ='Data Sheet'!K58 -> 106878
A6: Borrowings | B6: ='Data Sheet'!B59 -> 289 | C6: ='Data Sheet'!C59 -> 247 | D6: ='Data Sheet'!D59 -> 62 | E6: ='Data Sheet'!E59 -> 8174 | F6: ='Data Sheet'!F59 -> 7795 | G6: ='Data Sheet'!G59 -> 7818 | H6: ='Data Sheet'!H59 -> 7688 | I6: ='Data Sheet'!I59 -> 8021 | ... K6: ='Data Sheet'!K59 -> 11283
A7: Other Liabilities | B7: ='Data Sheet'!B60 -> 15830 | C7: ='Data Sheet'!C60 -> 19751 | D7: ='Data Sheet'!D60 -> 24393 | E7: ='Data Sheet'!E60 -> 27827 | F7: ='Data Sheet'!F60 -> 35764 | G7: ='Data Sheet'!G60 -> 43967 | H7: ='Data Sheet'!H60 -> 44747 | I7: ='Data Sheet'!I60 -> 46962 | ... K7: ='Data Sheet'!K60 -> 63849
A8: Total | B8: ='Data Sheet'!B61 -> 102333 | C8: ='Data Sheet'!C61 -> 105126 | D8: ='Data Sheet'!D61 -> 113901 | E8: ='Data Sheet'!E61 -> 120127 | F8: ='Data Sheet'!F61 -> 129992 | G8: ='Data Sheet'!G61 -> 140924 | H8: ='Data Sheet'!H61 -> 142859 | I8: ='Data Sheet'!I61 -> 145472 | ... K8: ='Data Sheet'!K61 -> 182372
A10: Net Block | B10: ='Data Sheet'!B62 -> 11701 | C10: ='Data Sheet'!C62 -> 11973 | D10: ='Data Sheet'!D62 -> 12290 | E10: ='Data Sheet'!E62 -> 20928 | F10: ='Data Sheet'!F62 -> 21021 | G10: ='Data Sheet'!G62 -> 21298 | H10: ='Data Sheet'!H62 -> 20515 | I10: ='Data Sheet'!I62 -> 19604 | ... K10: ='Data Sheet'!K62 -> 31343
A11: Capital Work in Progress | B11: ='Data Sheet'!B63 -> 1541 | C11: ='Data Sheet'!C63 -> 1278 | D11: ='Data Sheet'!D63 -> 963 | E11: ='Data Sheet'!E63 -> 906 | F11: ='Data Sheet'!F63 -> 926 | G11: ='Data Sheet'!G63 -> 1205 | H11: ='Data Sheet'!H63 -> 1234 | I11: ='Data Sheet'!I63 -> 1564 | ... K11: ='Data Sheet'!K63 -> 2665
A12: Investments | B12: ='Data Sheet'!B64 -> 41980 | C12: ='Data Sheet'!C64 -> 36008 | D12: ='Data Sheet'!D64 -> 29330 | E12: ='Data Sheet'!E64 -> 26356 | F12: ='Data Sheet'!F64 -> 29373 | G12: ='Data Sheet'!G64 -> 30485 | H12: ='Data Sheet'!H64 -> 37163 | I12: ='Data Sheet'!I64 -> 31762 | ... K12: ='Data Sheet'!K64 -> 33988
A13: Other Assets | B13: ='Data Sheet'!B65 -> 47111 | C13: ='Data Sheet'!C65 -> 55867 | D13: ='Data Sheet'!D65 -> 71318 | E13: ='Data Sheet'!E65 -> 71937 | F13: ='Data Sheet'!F65 -> 78672 | G13: ='Data Sheet'!G65 -> 87936 | H13: ='Data Sheet'!H65 -> 83947 | I13: ='Data Sheet'!I65 -> 92542 | ... K13: ='Data Sheet'!K65 -> 114376
A14: Total | B14: ='Data Sheet'!B66 -> 102333 | C14: ='Data Sheet'!C66 -> 105126 | D14: ='Data Sheet'!D66 -> 113901 | E14: ='Data Sheet'!E66 -> 120127 | F14: ='Data Sheet'!F66 -> 129992 | G14: ='Data Sheet'!G66 -> 140924 | H14: ='Data Sheet'!H66 -> 142859 | I14: ='Data Sheet'!I66 -> 145472 | ... K14: ='Data Sheet'!K66 -> 182372
A16: Working Capital | B16: =B13-B7 -> 31281 | C16: =C13-C7 -> 36116 | D16: =D13-D7 -> 46925 | E16: =E13-E7 -> 44110 | F16: =F13-F7 -> 42908 | G16: =G13-G7 -> 43969 | H16: =H13-H7 -> 39200 | I16: =I13-I7 -> 45580 | ... K16: =K13-K7 -> 50527
A17: Debtors | B17: ='Data Sheet'!B67 -> 22617 | C17: ='Data Sheet'!C67 -> 24943 | D17: ='Data Sheet'!D67 -> 27346 | E17: ='Data Sheet'!E67 -> 30532 | F17: ='Data Sheet'!F67 -> 30079 | G17: ='Data Sheet'!G67 -> 41810 | H17: ='Data Sheet'!H67 -> 49954 | I17: ='Data Sheet'!I67 -> 53577 | ... K17: ='Data Sheet'!K67 -> 57630
A18: Inventory | B18: ='Data Sheet'!B68 -> 21 | C18: ='Data Sheet'!C68 -> 26 | D18: ='Data Sheet'!D68 -> 10 | E18: ='Data Sheet'!E68 -> 5 | F18: ='Data Sheet'!F68 -> 8 | G18: ='Data Sheet'!G68 -> 20 | H18: ='Data Sheet'!H68 -> 28 | I18: ='Data Sheet'!I68 -> 28 | ... K18: ='Data Sheet'!K68 -> 29
A20: Debtor Days | B20: =IF('Profit & Loss'!B4>0,'Balance Sheet'!B17/('Profit & Loss'!B4/365),0) -> 69.979528 | C20: =IF('Profit & Loss'!C4>0,'Balance Sheet'!C17/('Profit & Loss'!C4/365),0) -> 73.955314 | D20: =IF('Profit & Loss'!D4>0,'Balance Sheet'!D17/('Profit & Loss'!D4/365),0) -> 68.148884 | E20: =IF('Profit & Loss'!E4>0,'Balance Sheet'!E17/('Profit & Loss'!E4/365),0) -> 71.005104 | F20: =IF('Profit & Loss'!F4>0,'Balance Sheet'!F17/('Profit & Loss'!F4/365),0) -> 66.871943 | G20: =IF('Profit & Loss'!G4>0,'Balance Sheet'!G17/('Profit & Loss'!G4/365),0) -> 79.58452 | H20: =IF('Profit & Loss'!H4>0,'Balance Sheet'!H17/('Profit & Loss'!H4/365),0) -> 80.87187 | I20: =IF('Profit & Loss'!I4>0,'Balance Sheet'!I17/('Profit & Loss'!I4/365),0) -> 81.179632 | ... K20: =IF('Profit & Loss'!K4>0,'Balance Sheet'!K17/('Profit & Loss'!K4/365),0) -> 78.776388
A21: Inventory Turnover | B21: =IF('Balance Sheet'!B18>0,'Profit & Loss'!B4/'Balance Sheet'!B18,0) -> 5617.4286 | C21: =IF('Balance Sheet'!C18>0,'Profit & Loss'!C4/'Balance Sheet'!C18,0) -> 4734.7692 | D21: =IF('Balance Sheet'!D18>0,'Profit & Loss'!D4/'Balance Sheet'!D18,0) -> 14646.3 | E21: =IF('Balance Sheet'!E18>0,'Profit & Loss'!E4/'Balance Sheet'!E18,0) -> 31389.8 | F21: =IF('Balance Sheet'!F18>0,'Profit & Loss'!F4/'Balance Sheet'!F18,0) -> 20522.125 | G21: =IF('Balance Sheet'!G18>0,'Profit & Loss'!G4/'Balance Sheet'!G18,0) -> 9587.7 | H21: =IF('Balance Sheet'!H18>0,'Profit & Loss'!H4/'Balance Sheet'!H18,0) -> 8052.0714 | I21: =IF('Balance Sheet'!I18>0,'Profit & Loss'!I4/'Balance Sheet'!I18,0) -> 8603.3214 | ... K21: =IF('Balance Sheet'!K18>0,'Profit & Loss'!K4/'Balance Sheet'!K18,0) -> 9207.6207
A23: Return on Equity | B23: =IF(SUM('Balance Sheet'!B4:B5)>0,'Profit & Loss'!B12/SUM('Balance Sheet'!B4:B5),"") -> 0.30492727 | C23: =IF(SUM('Balance Sheet'!C4:C5)>0,'Profit & Loss'!C12/SUM('Balance Sheet'!C4:C5),"") -> 0.30337844 | D23: =IF(SUM('Balance Sheet'!D4:D5)>0,'Profit & Loss'!D12/SUM('Balance Sheet'!D4:D5),"") -> 0.35185475 | E23: =IF(SUM('Balance Sheet'!E4:E5)>0,'Profit & Loss'!E12/SUM('Balance Sheet'!E4:E5),"") -> 0.38442336 | F23: =IF(SUM('Balance Sheet'!F4:F5)>0,'Profit & Loss'!F12/SUM('Balance Sheet'!F4:F5),"") -> 0.37520392 | G23: =IF(SUM('Balance Sheet'!G4:G5)>0,'Profit & Loss'!G12/SUM('Balance Sheet'!G4:G5),"") -> 0.42996892 | H23: =IF(SUM('Balance Sheet'!H4:H5)>0,'Profit & Loss'!H12/SUM('Balance Sheet'!H4:H5),"") -> 0.46610413 | I23: =IF(SUM('Balance Sheet'!I4:I5)>0,'Profit & Loss'!I12/SUM('Balance Sheet'!I4:I5),"") -> 0.50733238 | ... K23: =IF(SUM('Balance Sheet'!K4:K5)>0,'Profit & Loss'!K12/SUM('Balance Sheet'!K4:K5),"") -> 0.45887728
A24: Return on Capital Emp | C24: =IF((B4+B5+B6+C4+C5+C6)>0,('Profit & Loss'!C10+'Profit & Loss'!C9)*2/(B4+B5+B6+C4+C5+C6),"") -> 0.39730507 | D24: =IF((C4+C5+C6+D4+D5+D6)>0,('Profit & Loss'!D10+'Profit & Loss'!D9)*2/(C4+C5+C6+D4+D5+D6),"") -> 0.47758787 | E24: =IF((D4+D5+D6+E4+E5+E6)>0,('Profit & Loss'!E10+'Profit & Loss'!E9)*2/(D4+D5+D6+E4+E5+E6),"") -> 0.4749186 | F24: =IF((E4+E5+E6+F4+F5+F6)>0,('Profit & Loss'!F10+'Profit & Loss'!F9)*2/(E4+E5+E6+F4+F5+F6),"") -> 0.47603577 | G24: =IF((F4+F5+F6+G4+G5+G6)>0,('Profit & Loss'!G10+'Profit & Loss'!G9)*2/(F4+F5+F6+G4+G5+G6),"") -> 0.5489029 | H24: =IF((G4+G5+G6+H4+H5+H6)>0,('Profit & Loss'!H10+'Profit & Loss'!H9)*2/(G4+G5+G6+H4+H5+H6),"") -> 0.591442 | I24: =IF((H4+H5+H6+I4+I5+I6)>0,('Profit & Loss'!I10+'Profit & Loss'!I9)*2/(H4+H5+H6+I4+I5+I6),"") -> 0.63853485 | J24: =IF((I4+I5+I6+J4+J5+J6)>0,('Profit & Loss'!J10+'Profit & Loss'!J9)*2/(I4+I5+I6+J4+J5+J6),"") -> 0.65259699 | K24: =IF((J4+J5+J6+K4+K5+K6)>0,('Profit & Loss'!K10+'Profit & Loss'!K9)*2/(J4+J5+J6+K4+K5+K6),"") -> 0.59921588

Sheet Cash Flow
A1: ='Balance Sheet'!A1 -> TATA CONSULTANCY SERVICES LTD | E1: =UPDATE | J1: SCREENER.IN
A3: Narration | B3: ='Data Sheet'!B81 -> 42825 | C3: ='Data Sheet'!C81 -> 43190 | D3: ='Data Sheet'!D81 -> 43555 | E3: ='Data Sheet'!E81 -> 43921 | F3: ='Data Sheet'!F81 -> 44286 | G3: ='Data Sheet'!G81 -> 44651 | H3: ='Data Sheet'!H81 -> 45016 | I3: ='Data Sheet'!I81 -> 45382 | ... K3: ='Data Sheet'!K81 -> 46112
A4: Cash from Operating Activity | B4: ='Data Sheet'!B82 -> 25223 | C4: ='Data Sheet'!C82 -> 25067 | D4: ='Data Sheet'!D82 -> 28593 | E4: ='Data Sheet'!E82 -> 32369 | F4: ='Data Sheet'!F82 -> 38802 | G4: ='Data Sheet'!G82 -> 39949 | H4: ='Data Sheet'!H82 -> 41965 | I4: ='Data Sheet'!I82 -> 44338 | ... K4: ='Data Sheet'!K82 -> 52094
A5: Cash from Investing Activity | B5: ='Data Sheet'!B83 -> -16895 | C5: ='Data Sheet'!C83 -> 3104 | D5: ='Data Sheet'!D83 -> 1645 | E5: ='Data Sheet'!E83 -> 8968 | F5: ='Data Sheet'!F83 -> -7956 | G5: ='Data Sheet'!G83 -> -738 | H5: ='Data Sheet'!H83 -> 548 | I5: ='Data Sheet'!I83 -> 6091 | ... K5: ='Data Sheet'!K83 -> -12845
A6: Cash from Financing Activity | B6: ='Data Sheet'!B84 -> -11026 | C6: ='Data Sheet'!C84 -> -26885 | D6: ='Data Sheet'!D84 -> -27897 | E6: ='Data Sheet'!E84 -> -39915 | F6: ='Data Sheet'!F84 -> -32634 | G6: ='Data Sheet'!G84 -> -33581 | H6: ='Data Sheet'!H84 -> -47878 | I6: ='Data Sheet'!I84 -> -48536 | ... K6: ='Data Sheet'!K84 -> -42133
A7: Net Cash Flow | B7: ='Data Sheet'!B85 -> -2698 | C7: ='Data Sheet'!C85 -> 1286 | D7: ='Data Sheet'!D85 -> 2341 | E7: ='Data Sheet'!E85 -> 1422 | F7: ='Data Sheet'!F85 -> -1788 | G7: ='Data Sheet'!G85 -> 5630 | H7: ='Data Sheet'!H85 -> -5365 | I7: ='Data Sheet'!I85 -> 1893 | ... K7: ='Data Sheet'!K85 -> -2884

Sheet Customization
A1: How to use it?
A3: You can customize this workbook as you want.
B4: You can add custom formating, add conditional formating, add your own formulas… do ANYTHING.
B5: Please don't edit the "Data Sheet" only.
A7: After customization, you can upload this back on Screener.
B8: Upload on: | C8: https://www.screener.in/excel/
A10: Download your customized workbooks now onwards.
B11: Now whenever you will "Export to excel" from Screener, it will export your customized file.
A14: TESTING:
B15: This is a testing feature currently.
B16: You can report any formula errors on the worksheet at: support@screener.in

Sheet Data Sheet
A1: COMPANY NAME | B1: TATA CONSULTANCY SERVICES LTD | E1: =IF(B2<>B3, "A NEW VERSION OF THE WORKSHEET IS AVAILABLE", "")
A2: LATEST VERSION | B2: 2.1 | E2: PLEASE DO NOT MAKE ANY CHANGES TO THIS SHEET
A3: CURRENT VERSION | B3: 2.1
A5: META
A6: Number of shares | B6: =IF(B9>0, B9/B8, 0) -> 361.80144
A7: Face Value | B7: 1
A8: Current Price | B8: 2554.9
A9: Market Capitalization | B9: 924366.49
A15: PROFIT & LOSS
A16: Report Date | B16: 42825 | C16: 43190 | D16: 43555 | E16: 43921 | F16: 44286 | G16: 44651 | H16: 45016 | I16: 45382 | J16: 45747 | K16: 46112
A17: Sales | B17: 117966 | C17: 123104 | D17: 146463 | E17: 156949 | F17: 164177 | G17: 191754 | H17: 225458 | I17: 240893 | J17: 255324 | K17: 267021
A18: Raw Material Cost | B18: 94 | C18: 86 | D18: 40 | E18: 18 | F18: 14 | G18: 29 | H18: 37 | I18: 42 | J18: 49
A19: Change in Inventory | B19: 1
A20: Power and Fuel
A21: Other Mfr. Exp | B21: 2715 | C21: 2614 | D21: 2230 | E21: 1887 | F21: 1448 | G21: 1134 | H21: 1844 | I21: 3660 | J21: 11599
A22: Employee Cost | B22: 61621 | C22: 66396 | D22: 78246 | E22: 85952 | F22: 91814 | G22: 107554 | H22: 127522 | I22: 140131 | J22: 145788 | K22: 154994
A23: Selling and admin | B23: 16392 | C23: 16808 | D23: 20387 | E23: 20527 | F23: 18322 | G23: 23187 | H23: 28913 | I23: 24151 | J23: 20729
A24: Other Expenses | B24: 4834 | C24: 4684 | D24: 6054 | E24: 6456 | F24: 6033 | G24: 6793 | H24: 7883 | I24: 8613 | J24: 9752 | K24: 39629
A25: Other Income | B25: 4221 | C25: 3642 | D25: 4311 | E25: 4592 | F25: 1916 | G25: 4018 | H25: 3449 | I25: 3464 | J25: 3962 | K25: -124
A26: Depreciation | B26: 1987 | C26: 2014 | D26: 2056 | E26: 3529 | F26: 4065 | G26: 4604 | H26: 5022 | I26: 4985 | J26: 5242 | K26: 5560
A27: Interest | B27: 32 | C27: 52 | D27: 198 | E27: 924 | F27: 637 | G27: 784 | H27: 779 | I27: 778 | J27: 796 | K27: 1227
A28: Profit before tax | B28: 34513 | C28: 34092 | D28: 41563 | E28: 42248 | F28: 43760 | G28: 51687 | H28: 56907 | I28: 61997 | J28: 65331 | K28: 65487
A29: Tax | B29: 8156 | C29: 8212 | D29: 10001 | E29: 9801 | F29: 11198 | G29: 13238 | H29: 14604 | I29: 15898 | J29: 16534 | K29: 16033
A30: Net profit | B30: 26289 | C30: 25826 | D30: 31472 | E30: 32340 | F30: 32430 | G30: 38327 | H30: 42147 | I30: 45908 | J30: 48553 | K30: 49210
A31: Dividend Amount | B31: 9259 | C31: 9550 | D31: 11250 | E31: 27375 | F31: 14060 | G31: 15738 | H31: 42090 | I31: 26426 | J31: 45612 | K31: 39820
A40: Quarters
A41: Report Date | B41: 45291 | C41: 45382 | D41: 45473 | E41: 45565 | F41: 45657 | G41: 45747 | H41: 45838 | I41: 45930 | J41: 46022 | K41: 46112
A42: Sales | B42: 60583 | C42: 61237 | D42: 62613 | E42: 64259 | F42: 63973 | G42: 64479 | H42: 63437 | I42: 65799 | J42: 67087 | K42: 70698
A43: Expenses | B43: 44195 | C43: 44073 | D43: 45951 | E43: 47528 | F43: 46939 | G43: 47499 | H43: 46562 | I43: 47821 | J43: 48818 | K43: 51422
A44: Other Income | B44: -96 | C44: 1157 | D44: 962 | E44: 729 | F44: 1243 | G44: 1028 | H44: 1660 | I44: -268 | J44: -2273 | K44: 757
A45: Depreciation | B45: 1233 | C45: 1246 | D45: 1220 | E45: 1266 | F45: 1377 | G45: 1379 | H45: 1361 | I45: 1413 | J45: 1380 | K45: 1406
A46: Interest | B46: 230 | C46: 226 | D46: 173 | E46: 162 | F46: 234 | G46: 227 | H46: 195 | I46: 229 | J46: 538 | K46: 265
A47: Profit before tax | B47: 14829 | C47: 16849 | D47: 16231 | E47: 16032 | F47: 16666 | G47: 16402 | H47: 16979 | I47: 16068 | J47: 14078 | K47: 18362
A48: Tax | B48: 3732 | C48: 4347 | D48: 4126 | E48: 4077 | F48: 4222 | G48: 4109 | H48: 4160 | I48: 3937 | J48: 3358 | K48: 4578
A49: Net profit | B49: 11058 | C49: 12434 | D49: 12040 | E49: 11909 | F49: 12380 | G49: 12224 | H49: 12760 | I49: 12075 | J49: 10657 | K49: 13718
A50: Operating Profit | B50: 16388 | C50: 17164 | D50: 16662 | E50: 16731 | F50: 17034 | G50: 16980 | H50: 16875 | I50: 17978 | J50: 18269 | K50: 19276
A55: BALANCE SHEET
A56: Report Date | B56: 42825 | C56: 43190 | D56: 43555 | E56: 43921 | F56: 44286 | G56: 44651 | H56: 45016 | I56: 45382 | J56: 45747 | K56: 46112
A57: Equity Share Capital | B57: 197 | C57: 191 | D57: 375 | E57: 375 | F57: 370 | G57: 366 | H57: 366 | I57: 362 | J57: 362 | K57: 362
A58: Reserves | B58: 86017 | C58: 84937 | D58: 89071 | E58: 83751 | F58: 86063 | G58: 88773 | H58: 90058 | I58: 90127 | J58: 94394 | K58: 106878
...

Sheet DATA FOR WACC
B3: S.No. | C3: Name | D3: CMP Rs. | E3: Mar Cap Rs.Cr. | F3: Debt Rs.Cr. | G3: Debt / Eq | H3: Eq Cap Rs.Cr. | I3: Intreste
B4: 1 | C4: TCS | D4: 2554.9 | E4: 924366.49 | F4: 11283 | G4: 0.11 | H4: 362 | I4: 796
B5: 2 | C5: Infosys | D5: 1305.3 | E5: 529152.58 | F5: 8796 | G5: 0.11 | H5: 2024 | I5: 416
B6: 3 | C6: L&T Technology | D6: 3430.7 | E6: 36333.93 | F6: 630 | G6: 0.1 | H6: 21.2 | I6: 56

Sheet Common Size Statement
B1: Tata Consultancy Services Ltd
B4: Particulars | C4: ='Data Sheet'!B16 -> 42825 | D4: ='Data Sheet'!C16 -> 43190 | E4: ='Data Sheet'!D16 -> 43555 | F4: ='Data Sheet'!E16 -> 43921 | G4: ='Data Sheet'!F16 -> 44286 | H4: ='Data Sheet'!G16 -> 44651 | I4: ='Data Sheet'!H16 -> 45016 | J4: ='Data Sheet'!I16 -> 45382 | K4: ='Data Sheet'!J16 -> 45747
A6: # | B6: Income Statement
B7: ='Data Sheet'!A17 -> Sales | C7: ='Data Sheet'!B17 -> 117966 | D7: ='Data Sheet'!C17 -> 123104 | E7: ='Data Sheet'!D17 -> 146463 | F7: ='Data Sheet'!E17 -> 156949 | G7: ='Data Sheet'!F17 -> 164177 | H7: ='Data Sheet'!G17 -> 191754 | I7: ='Data Sheet'!H17 -> 225458 | ... K7: ='Data Sheet'!J17 -> 255324
B8: ='Data Sheet'!A18 -> Raw Material Cost | C8: ='Data Sheet'!B18 -> 94 | D8: ='Data Sheet'!C18 -> 86 | E8: ='Data Sheet'!D18 -> 40 | F8: ='Data Sheet'!E18 -> 18 | G8: ='Data Sheet'!F18 -> 14 | H8: ='Data Sheet'!G18 -> 29 | I8: ='Data Sheet'!H18 -> 37 | ... K8: ='Data Sheet'!J18 -> 49
B9: ='Data Sheet'!A21 -> Other Mfr. Exp | C9: ='Data Sheet'!B21 -> 2715 | D9: ='Data Sheet'!C21 -> 2614 | E9: ='Data Sheet'!D21 -> 2230 | F9: ='Data Sheet'!E21 -> 1887 | G9: ='Data Sheet'!F21 -> 1448 | H9: ='Data Sheet'!G21 -> 1134 | I9: ='Data Sheet'!H21 -> 1844 | ... K9: ='Data Sheet'!J21 -> 11599
B10: ='Data Sheet'!A22 -> Employee Cost | C10: ='Data Sheet'!B22 -> 61621 | D10: ='Data Sheet'!C22 -> 66396 | E10: ='Data Sheet'!D22 -> 78246 | F10: ='Data Sheet'!E22 -> 85952 | G10: ='Data Sheet'!F22 -> 91814 | H10: ='Data Sheet'!G22 -> 107554 | I10: ='Data Sheet'!H22 -> 127522 | ... K10: ='Data Sheet'!J22 -> 145788
B11: COGS | C11: =SUM(C8:C10) -> 64430 | D11: =SUM(D8:D10) -> 69096 | E11: =SUM(E8:E10) -> 80516 | F11: =SUM(F8:F10) -> 87857 | G11: =SUM(G8:G10) -> 93276 | H11: =SUM(H8:H10) -> 108717 | I11: =SUM(I8:I10) -> 129403 | J11: =SUM(J8:J10) -> 143833 | K11: =SUM(K8:K10) -> 157436
B12: Gross Profit | C12: =C7-C11 -> 53536 | D12: =D7-D11 -> 54008 | E12: =E7-E11 -> 65947 | F12: =F7-F11 -> 69092 | G12: =G7-G11 -> 70901 | H12: =H7-H11 -> 83037 | I12: =I7-I11 -> 96055 | J12: =J7-J11 -> 97060 | K12: =K7-K11 -> 97888
B13: ='Data Sheet'!A23 -> Selling and admin | C13: ='Data Sheet'!B23 -> 16392 | D13: ='Data Sheet'!C23 -> 16808 | E13: ='Data Sheet'!D23 -> 20387 | F13: ='Data Sheet'!E23 -> 20527 | G13: ='Data Sheet'!F23 -> 18322 | H13: ='Data Sheet'!G23 -> 23187 | I13: ='Data Sheet'!H23 -> 28913 | ... K13: ='Data Sheet'!J23 -> 20729
B14: ='Data Sheet'!A24 -> Other Expenses | C14: ='Data Sheet'!B24 -> 4834 | D14: ='Data Sheet'!C24 -> 4684 | E14: ='Data Sheet'!D24 -> 6054 | F14: ='Data Sheet'!E24 -> 6456 | G14: ='Data Sheet'!F24 -> 6033 | H14: ='Data Sheet'!G24 -> 6793 | I14: ='Data Sheet'!H24 -> 7883 | ... K14: ='Data Sheet'!J24 -> 9752
B15: EBIDTA | C15: =C12-SUM(C13:C14) -> 32310 | D15: =D12-SUM(D13:D14) -> 32516 | E15: =E12-SUM(E13:E14) -> 39506 | F15: =F12-SUM(F13:F14) -> 42109 | G15: =G12-SUM(G13:G14) -> 46546 | H15: =H12-SUM(H13:H14) -> 53057 | I15: =I12-SUM(I13:I14) -> 59259 | J15: =J12-SUM(J13:J14) -> 64296 | K15: =K12-SUM(K13:K14) -> 67407
B16: ='Data Sheet'!A26 -> Depreciation | C16: ='Data Sheet'!B26 -> 1987 | D16: ='Data Sheet'!C26 -> 2014 | E16: ='Data Sheet'!D26 -> 2056 | F16: ='Data Sheet'!E26 -> 3529 | G16: ='Data Sheet'!F26 -> 4065 | H16: ='Data Sheet'!G26 -> 4604 | I16: ='Data Sheet'!H26 -> 5022 | ... K16: ='Data Sheet'!J26 -> 5242
B17: ='Data Sheet'!A27 -> Interest | C17: ='Data Sheet'!B27 -> 32 | D17: ='Data Sheet'!C27 -> 52 | E17: ='Data Sheet'!D27 -> 198 | F17: ='Data Sheet'!E27 -> 924 | G17: ='Data Sheet'!F27 -> 637 | H17: ='Data Sheet'!G27 -> 784 | I17: ='Data Sheet'!H27 -> 779 | ... K17: ='Data Sheet'!J27 -> 796
B18: ='Data Sheet'!A28 -> Profit before tax | C18: =C15-SUM(C16:C17) -> 30291 | D18: =D15-SUM(D16:D17) -> 30450 | E18: =E15-SUM(E16:E17) -> 37252 | F18: =F15-SUM(F16:F17) -> 37656 | G18: =G15-SUM(G16:G17) -> 41844 | H18: =H15-SUM(H16:H17) -> 47669 | I18: =I15-SUM(I16:I17) -> 53458 | J18: =J15-SUM(J16:J17) -> 58533 | K18: =K15-SUM(K16:K17) -> 61369
B19: ='Data Sheet'!A25 -> Other Income | C19: ='Data Sheet'!B25 -> 4221 | D19: ='Data Sheet'!C25 -> 3642 | E19: ='Data Sheet'!D25 -> 4311 | F19: ='Data Sheet'!E25 -> 4592 | G19: ='Data Sheet'!F25 -> 1916 | H19: ='Data Sheet'!G25 -> 4018 | I19: ='Data Sheet'!H25 -> 3449 | ... K19: ='Data Sheet'!J25 -> 3962
B20: ='Data Sheet'!A29 -> Tax | C20: ='Data Sheet'!B29 -> 8156 | D20: ='Data Sheet'!C29 -> 8212 | E20: ='Data Sheet'!D29 -> 10001 | F20: ='Data Sheet'!E29 -> 9801 | G20: ='Data Sheet'!F29 -> 11198 | H20: ='Data Sheet'!G29 -> 13238 | I20: ='Data Sheet'!H29 -> 14604 | ... K20: ='Data Sheet'!J29 -> 16534
B21: ='Data Sheet'!A30 -> Net profit | C21: =SUM(C18:C19)-C20 -> 26356 | D21: =SUM(D18:D19)-D20 -> 25880 | E21: =SUM(E18:E19)-E20 -> 31562 | F21: =SUM(F18:F19)-F20 -> 32447 | G21: =SUM(G18:G19)-G20 -> 32562 | H21: =SUM(H18:H19)-H20 -> 38449 | I21: =SUM(I18:I19)-I20 -> 42303 | J21: =SUM(J18:J19)-J20 -> 46099 | K21: =SUM(K18:K19)-K20 -> 48797
B23: ='Data Sheet'!A93 -> Adjusted Equity Shares in Cr | C23: ='Data Sheet'!B93 -> 394.09 | D23: ='Data Sheet'!C93 -> 382.86 | E23: ='Data Sheet'!D93 -> 375.24 | F23: ='Data Sheet'!E93 -> 375.24 | G23: ='Data Sheet'!F93 -> 369.91 | H23: ='Data Sheet'!G93 -> 365.91 | I23: ='Data Sheet'!H93 -> 365.91 | ... K23: ='Data Sheet'!J93 -> 361.81
B24: Earnings Per Share (EPS) | C24: =C21/C23 -> 66.878124 | D24: =D21/D23 -> 67.59651 | E24: =E21/E23 -> 84.111502 | F24: =F21/F23 -> 86.469993 | G24: =G21/G23 -> 88.026817 | H24: =H21/H23 -> 105.07775 | I24: =I21/I23 -> 115.6104 | J24: =J21/J23 -> 127.41218 | K24: =K21/K23 -> 134.86913
B26: ='Data Sheet'!A31 -> Dividend Amount | C26: ='Data Sheet'!B31 -> 9259 | D26: ='Data Sheet'!C31 -> 9550 | E26: ='Data Sheet'!D31 -> 11250 | F26: ='Data Sheet'!E31 -> 27375 | G26: ='Data Sheet'!F31 -> 14060 | H26: ='Data Sheet'!G31 -> 15738 | I26: ='Data Sheet'!H31 -> 42090 | ... K26: ='Data Sheet'!J31 -> 45612
B27: Retained Earing | C27: =C21-C26 -> 17097 | D27: =D21-D26 -> 16330 | E27: =E21-E26 -> 20312 | F27: =F21-F26 -> 5072 | G27: =G21-G26 -> 18502 | H27: =H21-H26 -> 22711 | I27: =I21-I26 -> 213 | J27: =J21-J26 -> 19673 | K27: =K21-K26 -> 3185
A29: # | B29: ="Common Size Income Statement"& " "&" - "&B1 -> Common Size Income Statement - Tata Consultancy Services Ltd
B31: Revenue | C31: =C7/C$7 -> 1 | D31: =D7/D$7 -> 1 | E31: =E7/E$7 -> 1 | F31: =F7/F$7 -> 1 | G31: =G7/G$7 -> 1 | H31: =H7/H$7 -> 1 | I31: =I7/I$7 -> 1 | J31: =J7/J$7 -> 1 | K31: =K7/K$7 -> 1
B32: COGS | C32: =C11/C$7 -> 0.54617432 | D32: =D11/D$7 -> 0.56128152 | E32: =E11/E$7 -> 0.54973611 | F32: =F11/F$7 -> 0.55978057 | G32: =G11/G$7 -> 0.56814292 | H32: =H11/H$7 -> 0.56696079 | I32: =I11/I$7 -> 0.57395612 | J32: =J11/J$7 -> 0.59708252 | K32: =K11/K$7 -> 0.61661262
B33: Gross Profit | C33: =C12/C$7 -> 0.45382568 | D33: =D12/D$7 -> 0.43871848 | E33: =E12/E$7 -> 0.45026389 | F33: =F12/F$7 -> 0.44021943 | G33: =G12/G$7 -> 0.43185708 | H33: =H12/H$7 -> 0.43303921 | I33: =I12/I$7 -> 0.42604388 | J33: =J12/J$7 -> 0.40291748 | K33: =K12/K$7 -> 0.38338738
B34: Selling & General Expenses | C34: =SUM(C13:C14)/C$7 -> 0.1799332 | D34: =SUM(D13:D14)/D$7 -> 0.17458409 | E34: =SUM(E13:E14)/E$7 -> 0.18053024 | F34: =SUM(F13:F14)/F$7 -> 0.17192209 | G34: =SUM(G13:G14)/G$7 -> 0.14834599 | H34: =SUM(H13:H14)/H$7 -> 0.15634615 | I34: =SUM(I13:I14)/I$7 -> 0.16320556 | J34: =SUM(J13:J14)/J$7 -> 0.13601059 | K34: =SUM(K13:K14)/K$7 -> 0.11938165
B35: EBITDA | C35: =C15/C$7 -> 0.27389248 | D35: =D15/D$7 -> 0.26413439 | E35: =E15/E$7 -> 0.26973365 | F35: =F15/F$7 -> 0.26829734 | G35: =G15/G$7 -> 0.28351109 | H35: =H15/H$7 -> 0.27669305 | I35: =I15/I$7 -> 0.26283831 | J35: =J15/J$7 -> 0.26690688 | K35: =K15/K$7 -> 0.26400573
B36: Depreciation | C36: =C16/C$7 -> 0.016843836 | D36: =D16/D$7 -> 0.016360151 | E36: =E16/E$7 -> 0.014037675 | F36: =F16/F$7 -> 0.022485011 | G36: =G16/G$7 -> 0.024759863 | H36: =H16/H$7 -> 0.024009929 | I36: =I16/I$7 -> 0.022274659 | J36: =J16/J$7 -> 0.020693835 | K36: =K16/K$7 -> 0.020530777
B37: Interest | C37: =C17/C$7 -> 0.0002712646 | D37: =D17/D$7 -> 0.00042240707 | E37: =E17/E$7 -> 0.0013518773 | F37: =F17/F$7 -> 0.0058872627 | G37: =G17/G$7 -> 0.0038799588 | H37: =H17/H$7 -> 0.0040885718 | I37: =I17/I$7 -> 0.003455189 | J37: =J17/J$7 -> 0.0032296497 | K37: =K17/K$7 -> 0.0031176074
B38: PBT | C38: =C18/C$7 -> 0.25677738 | D38: =D18/D$7 -> 0.24735183 | E38: =E18/E$7 -> 0.2543441 | F38: =F18/F$7 -> 0.23992507 | G38: =G18/G$7 -> 0.25487127 | H38: =H18/H$7 -> 0.24859455 | I38: =I18/I$7 -> 0.23710846 | J38: =J18/J$7 -> 0.2429834 | K38: =K18/K$7 -> 0.24035735
B39: Taxes | C39: =C20/C$7 -> 0.069138565 | D39: =D20/D$7 -> 0.066707824 | E39: =E20/E$7 -> 0.068283457 | F39: =F20/F$7 -> 0.062447037 | G39: =G20/G$7 -> 0.068206874 | H39: =H20/H$7 -> 0.06903637 | I39: =I20/I$7 -> 0.064774814 | J39: =J20/J$7 -> 0.065996106 | K39: =K20/K$7 -> 0.064756936
B40: Net Income | C40: =C21/C$7 -> 0.22342031 | D40: =D21/D$7 -> 0.21022875 | E40: =E21/E$7 -> 0.2154947 | F40: =F21/F$7 -> 0.20673595 | G40: =G21/G$7 -> 0.19833472 | H40: =H21/H$7 -> 0.20051211 | I40: =I21/I$7 -> 0.1876314 | J40: =J21/J$7 -> 0.19136712 | K40: =K21/K$7 -> 0.19111795
B42: EPS- Growth | C42: NA | D42: =D24/C24-1 -> 0.010741722 | E42: =E24/D24-1 -> 0.24431722 | F42: =F24/E24-1 -> 0.028040048 | G42: =G24/F24-1 -> 0.01800422 | H42: =H24/G24-1 -> 0.19370158 | I42: =I24/H24-1 -> 0.10023668 | J42: =J24/I24-1 -> 0.10208236 | K42: =K24/J24-1 -> 0.058526215
B44: Dividend % of PAT | C44: =C26/C21 -> 0.35130521 | D44: =D26/D21 -> 0.36901082 | E44: =E26/E21 -> 0.35644129 | F44: =F26/F21 -> 0.84368355 | G44: =G26/G21 -> 0.43179166 | H44: =H26/H21 -> 0.40932144 | I44: =I26/I21 -> 0.9949649 | J44: =J26/J21 -> 0.57324454 | K44: =K26/K21 -> 0.93472959
B45: Retained Earing | C45: =1-C44 -> 0.64869479 | D45: =1-D44 -> 0.63098918 | E45: =1-E44 -> 0.64355871 | F45: =1-F44 -> 0.15631645 | G45: =1-G44 -> 0.56820834 | H45: =1-H44 -> 0.59067856 | I45: =1-I44 -> 0.0050351039 | J45: =1-J44 -> 0.42675546 | K45: =1-K44 -> 0.065270406

Sheet Capital  Budgeting
B2: Capital Budgeting Analysis
B4: NPV,IRR,and Payback Period
B6: Project
B7: Period | C7: 0 | D7: =C7+1 -> 1 | E7: =D7+1 -> 2 | F7: =E7+1 -> 3 | G7: =F7+1 -> 4
B8: Cash Inflow | C8: -5000000 | D8: 1500000 | E8: 2000000 | F8: 2500000 | G8: 3000000
B9: Cumulated Cash Flow | C9: =C8 -> -5000000 | D9: =D8+C9 -> -3500000 | E9: =E8+D9 -> -1500000 | F9: =F8+E9 -> 1000000 | G9: =G8+F9 -> 4000000
C12: Discount Rate | D12: 0.12
C13: NPV | D13: =NPV(D12,D8:G8)+C8 -> 1619678.3
C14: IRR | D14: =IRR(C8:G8) -> 0.24888336
C15: Pay Back Period | D15: =2+F9/G8 -> 2.3333333
B18: Manual (step-by-step) way to calculate NPV
C20: Total Investment | D20: 5000000 | F20: Discount Rate | G20: =D12 -> 0.12
C22: Years | D22: Cash Inflow | E22: Periodic PV | F22: Present value
C23: 1 | D23: {=TRANSPOSE(D8:G8)} -> 1500000 | E23: =1/1.12 -> 0.89285714 | F23: =D23*E23 -> 1339285.7
C24: =C23+1 -> 2 | D24: 2000000 | E24: =E23/1.12 -> 0.79719388 | F24: =D24*E24 -> 1594387.8
C25: =C24+1 -> 3 | D25: 2500000 | E25: =E24/1.12 -> 0.71178025 | F25: =D25*E25 -> 1779450.6
C26: =C25+1 -> 4 | D26: 3000000 | E26: =E25/1.12 -> 0.63551808 | F26: =D26*E26 -> 1906554.2
E27: Total PV | F27: =SUM(F23:F26) -> 6619678.3
D29: NPV | E29: =F27-D20 -> 1619678.3
B33: Key Reasons to Proceed with the Project:
A34: # | B34: Positive NPV:
B35: The project adds value, generating a surplus of ₹16,19,678 over the required return.
A36: # | B36: Higher IRR than Required Return:
B37: The project earns more than the minimum expected return, making it financially attractive
A38: # | B38: Quick Payback:
B39: Investment is recovered in 2 years and 3 months, reducing risk and improving liquidity.

Sheet Leverage
B2: Tata Motors
B3: Sales | D3: 300000
B4: Variable Cost | D4: 210000
B5: Contribution (Gross Profit) | D5: =D3-D4 -> 90000
B6: Fixed Operating Cost | D6: 40000
B7: EBIT | D7: =D5-D6 -> 50000
B8: Interest Expense | D8: 8000
B9: EBT | D9: =D7-D8 -> 42000
B11: Compute Operating Leverage (OL) | D11: =D5/D7 -> 1.8
B12: Compute Financial Leverage (FL) | D12: =D7/D9 -> 1.1904762
B13: Compute Combined Leverage (CL) | D13: =D11*D12 -> 2.1428571

Sheet WACC
B1: Weighted Average Cost of Capital
B4: Peer Comparable WACC
B5: Weekly - Two Year Range
G6: Debt/ | H6: Debt / | I6: levered | J6: Unlevered
B7: Name of The comps | C7: Country | D7: Total Debt | E7: Total Equity | F7: Tax Rate 1 | G7: Equity | H7: Capital | I7: Beta 2 | J7: Beta 3
B9: TCS | C9: India | D9: ='DATA FOR WACC'!F4 -> 11283 | E9: ='DATA FOR WACC'!E4 -> 924366.49 | F9: 0.3 | G9: =D9/E9 -> 0.012206198 | H9: =D9/(D9+E9) -> 0.012059003 | I9: 0.89 | J9: =I9/(1+(1-F9)*G9) -> 0.88245996
B10: Infosys | C10: India | D10: ='DATA FOR WACC'!F5 -> 8796 | E10: ='DATA FOR WACC'!E5 -> 529152.58 | F10: 0.3 | G10: =D10/E10 -> 0.016622805 | H10: =D10/(D10+E10) -> 0.016351005 | I10: 0.75 | J10: =I10/(1+(1-F10)*G10) -> 0.74137341
B11: L&T Technology | C11: India | D11: ='DATA FOR WACC'!F6 -> 630 | E11: ='DATA FOR WACC'!E6 -> 36333.93 | F11: 0.3 | G11: =D11/E11 -> 0.017339165 | H11: =D11/(D11+E11) -> 0.017043642 | I11: 0.97 | J11: =I11/(1+(1-F11)*G11) -> 0.95836789
E13: Average | F13: =AVERAGE(F9:F11) -> 0.3 | G13: =AVERAGE(G9:G11) -> 0.015389389 | H13: =AVERAGE(H9:H11) -> 0.015151217 | I13: =AVERAGE(I9:I11) -> 0.87 | J13: =AVERAGE(J9:J11) -> 0.86073375
E14: Median | F14: =MEDIAN(F9:F11) -> 0.3 | G14: =MEDIAN(G9:G11) -> 0.016622805 | H14: =MEDIAN(H9:H11) -> 0.016351005 | I14: =MEDIAN(I9:I11) -> 0.89 | J14: =MEDIAN(J9:J11) -> 0.88245996
B17: Cost of Debt | G17: Cost Of Equity
B19: Pre-Tax Cost of Debt | E19: ='DATA FOR WACC'!I4/'DATA FOR WACC'!F4 -> 0.070548613 | G19: Risk Free Rate | J19: 0.0686
B20: Tax rate | E20: =F11 -> 0.3 | G20: Equity Risk Premium | J20: =[1]DCF!F4-[1]DCF!J18 -> 0
B21: Post Tax Cost of Debt | E21: =E19*(1-E20) -> 0.049384029 | G21: Levered Beta 4 | J21: =J31 -> 0.89196319
G22: Cost Of Equity | J22: =J19+J20*J21 -> 0.0686
B26: Capital Structure | G26: Levered Beta
D28: Current | E28: Target | G28: Comps Median Unlevered Beta | J28: =J14 -> 0.88245996
B29: Total Debt | C29: =D9 -> 11283 | D29: =C29/C31 -> 0.012059003 | E29: =H13 -> 0.015151217 | G29: Target Debt/Equity | J29: =E34 -> 0.015384308
B30: Market Capitalization | C30: =E9 -> 924366.49 | D30: =C30/C31 -> 0.987941 | E30: =E31-E29 -> 0.98484878 | G30: Tax Rate | J30: =E20 -> 0.3
B31: Total Capital | C31: =SUM(C29:C30) -> 935649.49 | D31: =C31/C31 -> 1 | E31: =D31/D31 -> 1 | G31: Levered Beta | J31: =J28*(1+(1-J30)*J29) -> 0.89196319
B34: Debt / Equity | D34: =D29/D30 -> 0.012206198 | E34: =E29/E30 -> 0.015384308 | G34: Weighted Average Cost of Capital
G35: Cost of Equity | J35: =J22 -> 0.0686
G36: Equity Weight | J36: =E30 -> 0.98484878
G38: Cost of Debt | J38: =E21 -> 0.049384029
G39: Debt Weight | J39: =E29 -> 0.015151217
G40: WACC | J40: =(J35*J36)+(J38*J39) -> 0.068308855

Sheet Bond Analysis
B1: Bond Analysis - 2 listed Government vs Corporate Bond
B4: ANDHRA PRADESH STATE BEVERAGES BOND | E4: KERALA INFRASTRUCTURE INVESTMENT FUND BOARD
B5: Features | C5: Value | E5: Features | F5: Value
B6: Face Value | C6: 100000 | E6: Face Value | F6: 100000
B7: Coupon Rate | C7: 0.088 | E7: Coupon Rate | F7: 0.093
B8: Maturity Date | C8: 26 Feb 2027, Fri | E8: Maturity Date | F8: Jan 21, 2030
B9: Market Price | C9: 1,01,950.16 | E9: Market Price | F9: 1,00,632.48
B10: YTM | C10: 0.0915 | E10: YTM | F10: 0.0935
B11: Type of Security | C11: State Guaranteed Bond (SLU) | E11: Type of Security | F11: State Guaranteed Bond (SLU)
B12: Rating | C12: ACUITE AA(CE) | E12: Rating | F12: Ind-Ra AA(CE)
B13: Int. Payment Frequency | C13: QUARTERLY | E13: Int. Payment Frequency | F13: QUARTERLY
B15: Suitable for investment in Gov Bond :- | C15: Kerala Infrastructure Investment Fund Board
B16: Higher YTM (Return):- | C16: KIIFB: 9.35% > Andhra: 9.15%
B17: Same Safety Level:- | C17: Both rated AA (CE)
B18: Higher Coupon Income:- | C18: KIIFB: 9.30% > Andhra: 8.80%
B19: Better Market Price Advantage:- | C19: KIIFB price ≈ near Face Value(₹1,00,632)
B22: NAVI FINSERV LIMITED | E22: MUTHOOT MCRED LIMITED
B23: Features | C23: Value | E23: Features | F23: Value
B24: Face Value | C24: 10000 | E24: Face Value | F24: 10000
B25: Coupon Rate | C25: 0.103 | E25: Coupon Rate | F25: 0.0965
B26: Maturity Date | C26: Sep 30, 2027 | E26: Maturity Date | F26: Sep 18, 2028
B27: Market Price | C27: 9992.13 | E27: Market Price | F27: 9829.89
B28: YTM | C28: 0.11 | E28: YTM | F28: 0.1105
B29: Type of Security | C29: Secured - Regular Bond/Debenture | E29: Type of Security | F29: Secured - Regular Bond/Debenture
B30: Rating | C30: CRISIL A | E30: Rating | F30: ICRA A
B31: Int. Payment Frequency | C31: MONTHLY | E31: Int. Payment Frequency | F31: MONTHLY
B34: Suitable for investment in Gov Bond :- | C34: Navi Finserv Limited
B35: Higher Coupon Rate (Better Income):- | C35: Navi: 10.30% > Muthoot: 9.65%
B36: Near Maturity Date (Lower Risk):- | C36: Navi matures earlier (2027) vs Muthoot (2028)
B37: Same Risk Level (Low to Moderate):- | C37: Both are A-rated = low to moderate risk cat
B38: Additional Insight:- | C38: YTM difference = only ~0.05% (very small)

Sheet Investment Portfolio
B1: Investment Portfolio (₹10,00,000 | Age 26 | 5+ Years)
B3: Asset Class | C3: Sub Allocation | D3: % Allocation | E3: Amount | F3: Notes
B5: Stocks (Total 40%) | C5: Large Cap | D5: 0.1 | E5: 100000 | F5: Stable, blue-chip companies
C6: Mid Cap | D6: 0.2 | E6: 200000 | F6: Growth-oriented companies
C7: Index ETF | D7: 0.1 | E7: 100000 | F7: Passive investing (Nifty/Sensex)
B8: Mutual Funds | C8: Stocks / Debt | D8: 0.2 | E8: 200000 | F8: lump sum
B9: Bonds | C9: Corporate / Govt | D9: 0.1 | E9: 100000 | F9: Stable income, low–moderate risk
B10: Gold | C10: Digital Gold | D10: 0.15 | E10: 150000 | F10: Hedge against inflation
B11: Insurance | C11: Term Plan / Health Insurance | D11: 0.05 | E11: 50000 | F11: Protection + basic coverage
B12: FD (Emergency) | C12: Bank Fixed Deposit | D12: 0.1 | E12: 100000 | F12: Liquidity & safety
B14: Invested Assets | C14: Total | D14: =SUM(D5:D12) -> 1 | E14: =SUM(E5:E12) -> 1000000

Sheet Dividend Analysis
B1: Dividend Analysis ( Infosys , HDFC Bank , Coal India )
B4: Income statement - Infosys Ltd | G4: Income statement - HDFC | L4: Income statement - Coal india
B6: Perticulars | C6: 44986 | D6: 45352 | E6: 45717 | G6: Perticulars | H6: 44986 | I6: 45352 | J6: 45717 | L6: Perticulars | M6: 44986 | N6: 45352 | O6: 45717
B7: Sales + | C7: 146767 | D7: 153670 | E7: 162990 | G7: Sales + | H7: 170754 | I7: 283649 | J7: 336367 | L7: Sales + | M7: 138252 | N7: 144762 | O7: 143369
B8: Expenses + | C8: 111637 | D8: 117245 | E8: 123754 | G8: Expenses + | H8: 77780 | I8: 154139 | J8: 183894 | L8: Expenses + | M8: 94020 | N8: 96791 | O8: 96305
B9: Operating Profit | C9: 35130 | D9: 36425 | E9: 39236 | G9: Operating Profit | H9: 63042 | I9: 174196 | J9: 186974 | L9: Operating Profit | M9: 44232 | N9: 47971 | O9: 47064
B10: OPM % | C10: 0.24 | D10: 0.24 | E10: 0.24 | G10: OPM % | H10: 29932 | I10: -44685 | J10: -34501 | L10: OPM % | M10: 0.32 | N10: 0.33 | O10: 0.33
B11: Other Income + | C11: 2701 | D11: 4711 | E11: 3600 | G11: Other Income + | H11: 0.18 | I11: -0.16 | J11: -0.1 | L11: Other Income + | M11: 6560 | N11: 8396 | O11: 9932
B12: Interest | C12: 284 | D12: 470 | E12: 416 | G12: Interest | H12: 33912 | I12: 124346 | J12: 134548 | L12: Interest | M12: 684 | N12: 819 | O12: 884
B13: Depreciation | C13: 4225 | D13: 4678 | E13: 4812 | G13: Depreciation | H13: 2345 | I13: 3092 | J13: 3805 | L13: Depreciation | M13: 6833 | N13: 6735 | O13: 9145
B14: Profit before tax | C14: 33322 | D14: 35988 | E14: 37608 | G14: Profit before tax | H14: 61498 | I14: 76569 | J14: 96242 | L14: Profit before tax | M14: 43275 | N14: 48813 | O14: 46966
B15: Tax % | C15: 0.28 | D15: 0.27 | E15: 0.29 | G15: Tax % | H15: 0.25 | I15: 0.15 | J15: 0.24 | L15: Tax % | M15: 0.27 | N15: 0.23 | O15: 0.25
B16: Net Profit | C16: 24108 | D16: 26248 | E16: 26750 | G16: Net Profit | H16: 46149 | I16: 65446 | J16: 73440 | L16: Net Profit | M16: 31723 | N16: 37369 | O16: 35302
B18: No of shares | C18: 413.8 | D18: 414.2 | E18: 414.6 | G18: No of shares | H18: 760 | I18: 765 | J18: 1536 | L18: No of shares | M18: 616.3 | N18: 616.3 | O18: 616.3
... B20: Dividend | C20: 13653 | D20: 14731 | E20: 20289 | G20: Dividend Paid | H20: 8605 | I20: 8404 | J20: 14826 | L20: Dividend Paid | M20: 14328 | N20: 15098 | O20: 16239
B22: EPS- Growth | C22: NA | D22: =D19/C19-1 -> 0.08815427 | E22: =E19/D19-1 -> 0.017721519 | G22: EPS- Growth | H22: NA | I22: =I19/H19-1 -> 0.08815427 | J22: =J19/I19-1 -> 0.017721519 | L22: EPS- Growth | M22: NA | N22: =N19/M19-1 -> 0.08815427 | O22: =O19/N19-1 -> 0.017721519
B24: Dividend Per Share | C24: =C20/C18 -> 32.9942 | D24: =D20/D18 -> 35.564944 | E24: =E20/E18 -> 48.936324 | G24: Dividend Per Share | H24: =H20/H18 -> 11.322368 | I24: =I20/I18 -> 10.985621 | J24: =J20/J18 -> 9.6523438 | L24: Dividend Per Share | M24: =M20/M18 -> 23.248418 | N24: =N20/N18 -> 24.49781 | O24: =O20/O18 -> 26.349181
B26: Dividend Payout % | C26: =C20/C16 -> 0.56632653 | D26: =D20/D16 -> 0.56122371 | E26: =E20/E16 -> 0.75846729 | G26: Dividend Payout % | H26: =H20/H16 -> 0.18646125 | I26: =I20/I16 -> 0.12841121 | J26: =J20/J16 -> 0.20187908 | L26: Dividend Payout % | M26: =M20/M16 -> 0.45165968 | N26: =N20/N16 -> 0.40402473 | O26: =O20/O16 -> 0.46000227
B27: Retained Earing | C27: =1-C26 -> 0.43367347 | D27: =1-D26 -> 0.43877629 | E27: =1-E26 -> 0.24153271 | G27: Retained Earing | H27: =1-H26 -> 0.81353875 | I27: =1-I26 -> 0.87158879 | J27: =1-J26 -> 0.79812092 | L27: Retained Earing | M27: =1-M26 -> 0.54834032 | N27: =1-N26 -> 0.59597527 | O27: =1-O26 -> 0.53999773
